Workbook

Sheet Instructions
A1: نظام حساب المعدل النهائي - SFE / LMS Grades Model
A3: الأوزان والمكونات
A4: المكون | B4: الوزن | C4: الدرجة الكلية | D4: ملاحظات
A5: التاسكات (Tasks) | B5: 20% | C5: 135 | D5: مجموع Task1 + Task2 + Task3
A6: الحضور (Attendance) | B6: 30% | C6: sessions × 20 | D6: عدد الحاضر × 20 (كل سيشن = 20)
A7: البروجيكت (Project) | B7: 50% | C7: 145 | D7: فردي 40 + جماعي 80 + بونص 25
A9: شروط النجاح
A10: 1. نسبة الحضور ≥ 60% (يحصل على الساعتين فقط إذا تجاوز الحضور 60%)
A11: 2. المعدل النهائي > 60%
A12: حالة النجاح = ناجح فقط إذا تحقق الشرطان معاً
A14: كيفية الاستخدام
A15: 1. في شيت Project_Teams: املأ الأعمدة الصفراء (Individual / Full Project / Bonus) لكل طالب.
A16: 2. درجات التاسكات والحضور تُسحب تلقائياً من شيت Source_Grades باستخدام Student ID. | C16: sessions × 20 | D16: عدد الحاضر × 20 (كل سيشن = 20)
A17: 3. جميع النسب والمعدل النهائي وحالة النجاح تُحسب تلقائياً بالصيغ.
A18: الحساب أصبح تلقائياً على كل السيشنات المدخلة (1-6). عند إدخال Session 5 أو 6 يتحدث العدد والنسبة تلقائياً حسب عدد السيشنات المملوءة.
A19: لا حاجة لتغيير يدوي: الصيغ تحسب تلقائياً عدد السيشنات المملوءة (COUNTA) ونسبة الحضور منها. | C19: sessions × 20 | D19: عدد الحاضر × 20 (كل سيشن = 20)
A20: 6. كل تيم مفصول بصرياً بحدود (بوكس) في شيت Project_Teams لتسهيل القراءة.
A21: ملاحظات تقنية
A22: - الخلايا الصفراء = مدخلات (Inputs) يجب ملؤها يدوياً
A23: - الخلايا الزرقاء الفاتحة = بيانات مستخرجة (Lookups) من Source_Grades
A24: - الخلايا الخضراء = حسابات آلية (Formulas)
A25: - المعدل النهائي = (Tasks% × 0.2) + (Attendance% × 0.3) + (Project% × 0.5)
A27: الألوان في حالة النجاح والحضور تتغير تلقائياً (أخضر = ناجح/نعم ، أحمر = لم ينجح/لا) | C27: sessions × 20 | D27: عدد الحاضر × 20 (كل سيشن = 20)
A29: تحديث هيكل درجات البروجيكت:
A30: 1. تم إنشاء شيت جديد اسمه Project_Scores لكتابة درجات البروجيكت (Individual / Full Project / Bonus).
A31: 2. الخلايا الصفراء في Project_Scores = مدخلات يدوية.
A32: 3. شيت Project_Teams بيسحب الدرجات تلقائياً من Project_Scores عن طريق Student ID.
A33: 4. اكتب درجة Full Project لكل طالب (أو انسخ نفس القيمة لكل أعضاء التيم).

Sheet Source_Grades
A1: Student ID | B1: Student Name | C1: Seat Number | D1: Academic Level | E1: Program | F1: Official Email | G1: Personal Email | H1: Phone | I1: Assigned Supporter (TA) | J1: Task 1 | K1: Task 2 | L1: Task 3 | M1: Total Tasks Score | N1: Bonus Points | O1: Session 1 | P1: Session 2 | Q1: Session 3 | R1: Session 4 | S1: Session 5 | T1: Session 6 | U1: Attended Sessions | V1: Attendance Rate (%) | W1: Total Score (Tasks + Bonus) | X1: Final Rank Score | Y1: Attended Count | Z1: Total Sessions | AA1: Final Score & Best attendance | AB1: Attended
A2: 20251700588 | B2: فيرونيكا امير رفعت جاد | C2: 20251700588 | D2: Level 1 | E2: General ( طلاب المستوى الأول والثاني خلال العام الدراسي السابق 25-26) | F2: 20251700588@cis.asu.edu.eg | G2: veroamir8@gmail.com | H2: 01016779505 | I2: رامز مجدي صبحي غالي | J2: 55 | K2: 45 | L2: 35 | M2: =IF(COUNTA(J2:L2)=0,0,SUM(J2:L2)) -> 135 | N2: 6 | O2: حاضر | P2: حاضر | Q2: حاضر | R2: حاضر | S2: حاضر | T2: {=IF(ISNUMBER(MATCH(TRIM(A2)&"", _xlfn._xlws.FILTER(TRIM(Project_Scores!$D$2:$D$300)&"", Project_Scores!$I$2:$I$300=TRUE, ""), 0)), "حاضر", "غائب")} -> غائب | U2: =IF(COUNTA(O2:T2)=0,"0 من 0",COUNTIF(O2:T2,"حاضر")&" من "&COUNTA(O2:T2)) -> 5 من 6 | V2: =IF(COUNTA(O2:T2)=0,0,COUNTIF(O2:T2,"حاضر")/COUNTA(O2:T2)) -> 0.83333333 | W2: =M2+N2 -> 141 | X2: 181 | Y2: =COUNTIF(O2:T2,"حاضر") -> 5 | Z2: =COUNTA(O2:T2) -> 6 | AA2: =COUNTIF(O2:T2,"حاضر")+(COUNTIF(O2:T2,"مستأذن")*0.5)+X2 -> 186 | AB2: =COUNTIF(T:T, "حاضر") -> 0 | AC2: Score Board (Top 15)
A3: 20241700031 | B3: احمد سامح حسن احمد محمد شوشه | C3: 20241700031 | D3: Level 2 | E3: General ( طلاب المستوى الأول والثاني خلال العام الدراسي السابق 25-26) | F3: 20241700031@cis.asu.edu.eg | G3: ahmedshosha2006@gmail.com | H3: 01026585928 | I3: رامز مجدي صبحي غالي | J3: 0 | K3: 0 | L3: 0 | M3: =IF(COUNTA(J3:L3)=0,0,SUM(J3:L3)) -> 0 | N3: 2 | O3: غائب | P3: غائب | Q3: غائب | R3: غائب | S3: غائب | T3: {=IF(ISNUMBER(MATCH(TRIM(A3)&"", _xlfn._xlws.FILTER(TRIM(Project_Scores!$D$2:$D$300)&"", Project_Scores!$I$2:$I$300=TRUE, ""), 0)), "حاضر", "غائب")} -> غائب | U3: =IF(COUNTA(O3:T3)=0,"0 من 0",COUNTIF(O3:T3,"حاضر")&" من "&COUNTA(O3:T3)) -> 0 من 6 | V3: =IF(COUNTA(O3:T3)=0,0,COUNTIF(O3:T3,"حاضر")/COUNTA(O3:T3)) -> 0 | W3: =M3+N3 -> 2 | X3: 2 | Y3: =COUNTIF(O3:T3,"حاضر") -> 0 | Z3: =COUNTA(O3:T3) -> 6 | AA3: =COUNTIF(O3:T3,"حاضر")+(COUNTIF(O3:T3,"مستأذن")*0.5)+X3 -> 2
A4: 20251700762 | B4: محمود محمد عبد الرسول كريم | C4: 20251700762 | D4: Level 1 | E4: General ( طلاب المستوى الأول والثاني خلال العام الدراسي السابق 25-26) | F4: 20251700762@cis.asu.edu.eg | G4: mahmoudmohamed20076@gmail.com | H4: 01507359655 | I4: شريف مصطفي عبد المنعم مصطفي | J4: 40 | K4: 25 | L4: 12 | M4: =IF(COUNTA(J4:L4)=0,0,SUM(J4:L4)) -> 77 | N4: 2 | O4: حاضر | P4: حاضر | Q4: حاضر | R4: حاضر | S4: حاضر | T4: {=IF(ISNUMBER(MATCH(TRIM(A4)&"", _xlfn._xlws.FILTER(TRIM(Project_Scores!$D$2:$D$300)&"", Project_Scores!$I$2:$I$300=TRUE, ""), 0)), "حاضر", "غائب")} -> غائب | U4: =IF(COUNTA(O4:T4)=0,"0 من 0",COUNTIF(O4:T4,"حاضر")&" من "&COUNTA(O4:T4)) -> 5 من 6 | V4: =IF(COUNTA(O4:T4)=0,0,COUNTIF(O4:T4,"حاضر")/COUNTA(O4:T4)) -> 0.83333333 | W4: =M4+N4 -> 79 | X4: 119 | Y4: =COUNTIF(O4:T4,"حاضر") -> 5 | Z4: =COUNTA(O4:T4) -> 6 | AA4: =COUNTIF(O4:T4,"حاضر")+(COUNTIF(O4:T4,"مستأذن")*0.5)+X4 -> 124 | AC4: {=_xlfn.TAKE(_xlfn.SORTBY(_xlfn.HSTACK(A2:B200, AA2:AA200), AA2:AA200, -1), 15)} -> 2023170234 | AD4: زياد أسامة مصطفى شلبى | AE4: 213
A5: 20251700531 | B5: عمر فؤاد محمد الشافعي | C5: 20251700531 | D5: Level 1 | E5: General ( طلاب المستوى الأول والثاني خلال العام الدراسي السابق 25-26) | F5: 20251700531@cis.asu.edu.eg | G5: omelshafiey@gmail.com | H5: 01211092805 | I5: عمر مصطفي سلامة علي | J5: 51 | K5: 45 | L5: 0 | M5: =IF(COUNTA(J5:L5)=0,0,SUM(J5:L5)) -> 96 | N5: 6 | O5: حاضر | P5: حاضر | Q5: حاضر | R5: حاضر | S5: حاضر | T5: {=IF(ISNUMBER(MATCH(TRIM(A5)&"", _xlfn._xlws.FILTER(TRIM(Project_Scores!$D$2:$D$300)&"", Project_Scores!$I$2:$I$300=TRUE, ""), 0)), "حاضر", "غائب")} -> غائب | U5: =IF(COUNTA(O5:T5)=0,"0 من 0",COUNTIF(O5:T5,"حاضر")&" من "&COUNTA(O5:T5)) -> 5 من 6 | V5: =IF(COUNTA(O5:T5)=0,0,COUNTIF(O5:T5,"حاضر")/COUNTA(O5:T5)) -> 0.83333333 | W5: =M5+N5 -> 102 | X5: 142 | Y5: =COUNTIF(O5:T5,"حاضر") -> 5 | Z5: =COUNTA(O5:T5) -> 6 | AA5: =COUNTIF(O5:T5,"حاضر")+(COUNTIF(O5:T5,"مستأذن")*0.5)+X5 -> 147 | AC5: 20251701124 | AD5: Aly Mohamed Mounir Aly Zaky Darwish | AE5: 212
A6: 2023170451 | B6: كيرلس مدحت مكرم عزمى | C6: 2023170451 | D6: Level 3 | E6: Information Systems | F6: 2023170451@cis.asu.edu.eg | G6: kirollos.medhat2005@gmail.com | H6: 01200501803 | I6: شريف مصطفي عبد المنعم مصطفي | J6: 55 | K6: 42 | L6: 36 | M6: =IF(COUNTA(J6:L6)=0,0,SUM(J6:L6)) -> 133 | N6: 0 | O6: حاضر | P6: حاضر | Q6: حاضر | R6: حاضر | S6: حاضر | T6: {=IF(ISNUMBER(MATCH(TRIM(A6)&"", _xlfn._xlws.FILTER(TRIM(Project_Scores!$D$2:$D$300)&"", Project_Scores!$I$2:$I$300=TRUE, ""), 0)), "حاضر", "غائب")} -> غائب | U6: =IF(COUNTA(O6:T6)=0,"0 من 0",COUNTIF(O6:T6,"حاضر")&" من "&COUNTA(O6:T6)) -> 5 من 6 | V6: =IF(COUNTA(O6:T6)=0,0,COUNTIF(O6:T6,"حاضر")/COUNTA(O6:T6)) -> 0.83333333 | W6: =M6+N6 -> 133 | X6: 173 | Y6: =COUNTIF(O6:T6,"حاضر") -> 5 | Z6: =COUNTA(O6:T6) -> 6 | AA6: =COUNTIF(O6:T6,"حاضر")+(COUNTIF(O6:T6,"مستأذن")*0.5)+X6 -> 178 | AC6: 20241700341 | AD6: زياد علاء محمد محمد | AE6: 201
A7: 20251700257 | B7: رؤى البدرى السيد توفيق | C7: 20251700257 | D7: Level 1 | E7: General ( طلاب المستوى الأول والثاني خلال العام الدراسي السابق 25-26) | F7: 20251700257@cis.asu.edu.eg | G7: roaelbadry8@gmail.com | H7: 01140159717 | I7: احمد اسماعيل سيد محمدي | J7: 41 | K7: 35 | L7: 30 | M7: =IF(COUNTA(J7:L7)=0,0,SUM(J7:L7)) -> 106 | N7: 4 | O7: حاضر | P7: حاضر | Q7: حاضر | R7: حاضر | S7: حاضر | T7: {=IF(ISNUMBER(MATCH(TRIM(A7)&"", _xlfn._xlws.FILTER(TRIM(Project_Scores!$D$2:$D$300)&"", Project_Scores!$I$2:$I$300=TRUE, ""), 0)), "حاضر", "غائب")} -> غائب | U7: =IF(COUNTA(O7:T7)=0,"0 من 0",COUNTIF(O7:T7,"حاضر")&" من "&COUNTA(O7:T7)) -> 5 من 6 | V7: =IF(COUNTA(O7:T7)=0,0,COUNTIF(O7:T7,"حاضر")/COUNTA(O7:T7)) -> 0.83333333 | W7: =M7+N7 -> 110 | X7: 150 | Y7: =COUNTIF(O7:T7,"حاضر") -> 5 | Z7: =COUNTA(O7:T7) -> 6 | AA7: =COUNTIF(O7:T7,"حاضر")+(COUNTIF(O7:T7,"مستأذن")*0.5)+X7 -> 155 | AC7: 20241701173 | AD7: أحمد عصام حسين محمود | AE7: 201
A8: 20251700511 | B8: عمر ايمن بدر عبد الفتاح | C8: 20251700511 | D8: Level 1 | E8: General ( طلاب المستوى الأول والثاني خلال العام الدراسي السابق 25-26) | F8: 20251700511@cis.asu.edu.eg | G8: omaraymanbadr77777@gmail.com | H8: 01013950802 | I8: ياسمين صلاح الدين عباس | J8: 40 | K8: 40 | L8: 15 | M8: =IF(COUNTA(J8:L8)=0,0,SUM(J8:L8)) -> 95 | N8: 2 | O8: حاضر | P8: مستأذن | Q8: حاضر | R8: حاضر | S8: حاضر | T8: {=IF(ISNUMBER(MATCH(TRIM(A8)&"", _xlfn._xlws.FILTER(TRIM(Project_Scores!$D$2:$D$300)&"", Project_Scores!$I$2:$I$300=TRUE, ""), 0)), "حاضر", "غائب")} -> غائب | U8: =IF(COUNTA(O8:T8)=0,"0 من 0",COUNTIF(O8:T8,"حاضر")&" من "&COUNTA(O8:T8)) -> 4 من 6 | V8: =IF(COUNTA(O8:T8)=0,0,COUNTIF(O8:T8,"حاضر")/COUNTA(O8:T8)) -> 0.66666667 | W8: =M8+N8 -> 97 | X8: 127 | Y8: =COUNTIF(O8:T8,"حاضر") -> 4 | Z8: =COUNTA(O8:T8) -> 6 | AA8: =COUNTIF(O8:T8,"حاضر")+(COUNTIF(O8:T8,"مستأذن")*0.5)+X8 -> 131.5 | AC8: 20241700920 | AD8: ندى محمود رياض نور الدين محمود | AE8: 199
A9: 20251700143 | B9: آيه خالد محمد نجيب | C9: 20251700143 | D9: Level 1 | E9: General ( طلاب المستوى الأول والثاني خلال العام الدراسي السابق 25-26) | F9: 20251700143@cis.asu.edu.eg | G9: ayakhaledelgazar2007@gmail.com | H9: 01001553655 | I9: احمد اسماعيل سيد محمدي | J9: 0 | K9: 0 | L9: 0 | M9: =IF(COUNTA(J9:L9)=0,0,SUM(J9:L9)) -> 0 | N9: 0 | O9: غائب | P9: غائب | Q9: غائب | R9: غائب | S9: غائب | T9: {=IF(ISNUMBER(MATCH(TRIM(A9)&"", _xlfn._xlws.FILTER(TRIM(Project_Scores!$D$2:$D$300)&"", Project_Scores!$I$2:$I$300=TRUE, ""), 0)), "حاضر", "غائب")} -> غائب | U9: =IF(COUNTA(O9:T9)=0,"0 من 0",COUNTIF(O9:T9,"حاضر")&" من "&COUNTA(O9:T9)) -> 0 من 6 | V9: =IF(COUNTA(O9:T9)=0,0,COUNTIF(O9:T9,"حاضر")/COUNTA(O9:T9)) -> 0 | W9: =M9+N9 -> 0 | X9: 0 | Y9: =COUNTIF(O9:T9,"حاضر") -> 0 | Z9: =COUNTA(O9:T9) -> 6 | AA9: =COUNTIF(O9:T9,"حاضر")+(COUNTIF(O9:T9,"مستأذن")*0.5)+X9 -> 0 | AC9: 20251700432 | AD9: عبدالله كرم ابوزيد سيف | AE9: 196.5
A10: 20251700720 | B10: محمد علي محمد علي | C10: 20251700720 | D10: Level 1 | E10: Computer Science | F10: 20251700720@cis.asu.edu.eg | G10: amro500880@gmail.com | H10: 01021164391 | I10: شريف مصطفي عبد المنعم مصطفي | J10: 0 | K10: 0 | L10: 0 | M10: =IF(COUNTA(J10:L10)=0,0,SUM(J10:L10)) -> 0 | N10: 0 | O10: حاضر | P10: غائب | Q10: غائب | R10: غائب | S10: غائب | T10: {=IF(ISNUMBER(MATCH(TRIM(A10)&"", _xlfn._xlws.FILTER(TRIM(Project_Scores!$D$2:$D$300)&"", Project_Scores!$I$2:$I$300=TRUE, ""), 0)), "حاضر", "غائب")} -> غائب | U10: =IF(COUNTA(O10:T10)=0,"0 من 0",COUNTIF(O10:T10,"حاضر")&" من "&COUNTA(O10:T10)) -> 1 من 6 | V10: =IF(COUNTA(O10:T10)=0,0,COUNTIF(O10:T10,"حاضر")/COUNTA(O10:T10)) -> 0.16666667 | W10: =M10+N10 -> 0 | X10: 10 | Y10: =COUNTIF(O10:T10,"حاضر") -> 1 | Z10: =COUNTA(O10:T10) -> 6 | AA10: =COUNTIF(O10:T10,"حاضر")+(COUNTIF(O10:T10,"مستأذن")*0.5)+X10 -> 11 | AC10: 20231700233 | AD10: علي عمرو محمد عبدالهادي | AE10: 191
A11: 20251700822 | B11: معاذ محمد السيد عبدالله | C11: 20251700822 | D11: Level 1 | E11: General ( طلاب المستوى الأول والثاني خلال العام الدراسي السابق 25-26) | F11: 20251700822@cis.asu.edu.eg | G11: m72946623@gmail.com | H11: 01091060853 | I11: شريف مصطفي عبد المنعم مصطفي | J11: 54 | K11: 32 | L11: 35 | M11: =IF(COUNTA(J11:L11)=0,0,SUM(J11:L11)) -> 121 | N11: 0 | O11: حاضر | P11: حاضر | Q11: حاضر | R11: حاضر | S11: حاضر | T11: {=IF(ISNUMBER(MATCH(TRIM(A11)&"", _xlfn._xlws.FILTER(TRIM(Project_Scores!$D$2:$D$300)&"", Project_Scores!$I$2:$I$300=TRUE, ""), 0)), "حاضر", "غائب")} -> غائب | U11: =IF(COUNTA(O11:T11)=0,"0 من 0",COUNTIF(O11:T11,"حاضر")&" من "&COUNTA(O11:T11)) -> 5 من 6 | V11: =IF(COUNTA(O11:T11)=0,0,COUNTIF(O11:T11,"حاضر")/COUNTA(O11:T11)) -> 0.83333333 | W11: =M11+N11 -> 121 | X11: 161 | Y11: =COUNTIF(O11:T11,"حاضر") -> 5 | Z11: =COUNTA(O11:T11) -> 6 | AA11: =COUNTIF(O11:T11,"حاضر")+(COUNTIF(O11:T11,"مستأذن")*0.5)+X11 -> 166 | AC11: 20241700935 | AD11: نوران محمد السيد محمد نصر | AE11: 190
A12: 20241700700 | B12: محمد اشرف محمد عبد المقصود | C12: 20241700700 | D12: Level 2 | E12: General ( طلاب المستوى الأول والثاني خلال العام الدراسي السابق 25-26) | F12: 20241700700@cis.asu.edu.eg | G12: wutthefq@gmail.com | H12: 01278244372 | I12: نور جاد علي جاد | J12: 38 | K12: 33 | L12: 29 | M12: =IF(COUNTA(J12:L12)=0,0,SUM(J12:L12)) -> 100 | N12: 7 | O12: حاضر | P12: حاضر | Q12: حاضر | R12: حاضر | S12: حاضر | T12: {=IF(ISNUMBER(MATCH(TRIM(A12)&"", _xlfn._xlws.FILTER(TRIM(Project_Scores!$D$2:$D$300)&"", Project_Scores!$I$2:$I$300=TRUE, ""), 0)), "حاضر", "غائب")} -> غائب | U12: =IF(COUNTA(O12:T12)=0,"0 من 0",COUNTIF(O12:T12,"حاضر")&" من "&COUNTA(O12:T12)) -> 5 من 6 | V12: =IF(COUNTA(O12:T12)=0,0,COUNTIF(O12:T12,"حاضر")/COUNTA(O12:T12)) -> 0.83333333 | W12: =M12+N12 -> 107 | X12: 147 | Y12: =COUNTIF(O12:T12,"حاضر") -> 5 | Z12: =COUNTA(O12:T12) -> 6 | AA12: =COUNTIF(O12:T12,"حاضر")+(COUNTIF(O12:T12,"مستأذن")*0.5)+X12 -> 152 | AC12: 20251700957 | AD12: يحيى صلاح الدين عباس السمان | AE12: 189
A13: 20241700948 | B13: هادي احمد هاشم احمد | C13: 20241700948 | D13: Level 2 | E13: General ( طلاب المستوى الأول والثاني خلال العام الدراسي السابق 25-26) | F13: 20241700948@cis.asu.edu.eg | G13: hady8705@gmail.com | H13: 01127816879 | I13: عبدالله هاني محمد نصر الدين عبدالحق | J13: 54 | K13: 32 | L13: 28 | M13: =IF(COUNTA(J13:L13)=0,0,SUM(J13:L13)) -> 114 | N13: 4 | O13: حاضر | P13: حاضر | Q13: حاضر | R13: حاضر | S13: حاضر | T13: {=IF(ISNUMBER(MATCH(TRIM(A13)&"", _xlfn._xlws.FILTER(TRIM(Project_Scores!$D$2:$D$300)&"", Project_Scores!$I$2:$I$300=TRUE, ""), 0)), "حاضر", "غائب")} -> غائب | U13: =IF(COUNTA(O13:T13)=0,"0 من 0",COUNTIF(O13:T13,"حاضر")&" من "&COUNTA(O13:T13)) -> 5 من 6 | V13: =IF(COUNTA(O13:T13)=0,0,COUNTIF(O13:T13,"حاضر")/COUNTA(O13:T13)) -> 0.83333333 | W13: =M13+N13 -> 118 | X13: 158 | Y13: =COUNTIF(O13:T13,"حاضر") -> 5 | Z13: =COUNTA(O13:T13) -> 6 | AA13: =COUNTIF(O13:T13,"حاضر")+(COUNTIF(O13:T13,"مستأذن")*0.5)+X13 -> 163 | AC13: 20241700089 | AD13: آدم محمد عطيتو السيد | AE13: 189
A14: 20251701037 | B14: آيه محمد اداره محمد | C14: 20251701037 | D14: Level 1 | E14: General ( طلاب المستوى الأول والثاني خلال العام الدراسي السابق 25-26) | F14: 20251701037@cis.asu.edu.eg | G14: aya904661@gmail.com | H14: 01207548255 | I14: نانسي محمد جلال عباس | J14: 55 | K14: 45 | L14: 20 | M14: =IF(COUNTA(J14:L14)=0,0,SUM(J14:L14)) -> 120 | N14: 0 | O14: غائب | P14: غائب | Q14: حاضر | R14: حاضر | S14: حاضر | T14: {=IF(ISNUMBER(MATCH(TRIM(A14)&"", _xlfn._xlws.FILTER(TRIM(Project_Scores!$D$2:$D$300)&"", Project_Scores!$I$2:$I$300=TRUE, ""), 0)), "حاضر", "غائب")} -> غائب | U14: =IF(COUNTA(O14:T14)=0,"0 من 0",COUNTIF(O14:T14,"حاضر")&" من "&COUNTA(O14:T14)) -> 3 من 6 | V14: =IF(COUNTA(O14:T14)=0,0,COUNTIF(O14:T14,"حاضر")/COUNTA(O14:T14)) -> 0.5 | W14: =M14+N14 -> 120 | X14: 140 | Y14: =COUNTIF(O14:T14,"حاضر") -> 3 | Z14: =COUNTA(O14:T14) -> 6 | AA14: =COUNTIF(O14:T14,"حاضر")+(COUNTIF(O14:T14,"مستأذن")*0.5)+X14 -> 143 | AC14: 2023170036 | AD14: احمد سليمان سعد عبدالحميد | AE14: 188
A15: 20251700009 | B15: أحمد ناصر بكر محمود | C15: 20251700009 | D15: Level 1 | E15: General ( طلاب المستوى الأول والثاني خلال العام الدراسي السابق 25-26) | F15: 20251700009@cis.asu.edu.eg | G15: a.safwat7197@gmail.com | H15: 01146113765 | I15: محمد طاهر محمد محمود | J15: 30 | K15: 30 | L15: 20 | M15: =IF(COUNTA(J15:L15)=0,0,SUM(J15:L15)) -> 80 | N15: 4 | O15: حاضر | P15: حاضر | Q15: حاضر | R15: حاضر | S15: حاضر | T15: {=IF(ISNUMBER(MATCH(TRIM(A15)&"", _xlfn._xlws.FILTER(TRIM(Project_Scores!$D$2:$D$300)&"", Project_Scores!$I$2:$I$300=TRUE, ""), 0)), "حاضر", "غائب")} -> غائب | U15: =IF(COUNTA(O15:T15)=0,"0 من 0",COUNTIF(O15:T15,"حاضر")&" من "&COUNTA(O15:T15)) -> 5 من 6 | V15: =IF(COUNTA(O15:T15)=0,0,COUNTIF(O15:T15,"حاضر")/COUNTA(O15:T15)) -> 0.83333333 | W15: =M15+N15 -> 84 | X15: 124 | Y15: =COUNTIF(O15:T15,"حاضر") -> 5 | Z15: =COUNTA(O15:T15) -> 6 | AA15: =COUNTIF(O15:T15,"حاضر")+(COUNTIF(O15:T15,"مستأذن")*0.5)+X15 -> 129 | AC15: 20241701556 | AD15: عامر وحيد هلال فرج | AE15: 187.5
A16: 20241700585 | B16: عمر وليد سعيد علي | C16: 20241700585 | D16: Level 2 | E16: General ( طلاب المستوى الأول والثاني خلال العام الدراسي السابق 25-26) | F16: 20241700585@cis.asu.edu.eg | G16: womar45689@gmail.com | H16: 01124150915 | I16: احمد اسماعيل سيد محمدي | J16: 52 | K16: 43 | L16: 35 | M16: =IF(COUNTA(J16:L16)=0,0,SUM(J16:L16)) -> 130 | N16: 0 | O16: حاضر | P16: حاضر | Q16: حاضر | R16: حاضر | S16: حاضر | T16: {=IF(ISNUMBER(MATCH(TRIM(A16)&"", _xlfn._xlws.FILTER(TRIM(Project_Scores!$D$2:$D$300)&"", Project_Scores!$I$2:$I$300=TRUE, ""), 0)), "حاضر", "غائب")} -> غائب | U16: =IF(COUNTA(O16:T16)=0,"0 من 0",COUNTIF(O16:T16,"حاضر")&" من "&COUNTA(O16:T16)) -> 5 من 6 | V16: =IF(COUNTA(O16:T16)=0,0,COUNTIF(O16:T16,"حاضر")/COUNTA(O16:T16)) -> 0.83333333 | W16: =M16+N16 -> 130 | X16: 170 | Y16: =COUNTIF(O16:T16,"حاضر") -> 5 | Z16: =COUNTA(O16:T16) -> 6 | AA16: =COUNTIF(O16:T16,"حاضر")+(COUNTIF(O16:T16,"مستأذن")*0.5)+X16 -> 175 | AC16: 20251700588 | AD16: فيرونيكا امير رفعت جاد | AE16: 186
... A18: 20241700374 | B18: سعيد مسعد سعيد محمد | C18: 20241700374 | D18: Level 2 | E18: General ( طلاب المستوى الأول والثاني خلال العام الدراسي السابق 25-26) | F18: 20241700374@cis.asu.edu.eg | G18: saeedseliem9@gmail.com | H18: 01008424741 | I18: نور جاد علي جاد | J18: 52 | K18: 29 | L18: 35 | M18: =IF(COUNTA(J18:L18)=0,0,SUM(J18:L18)) -> 116 | N18: 2 | O18: حاضر | P18: حاضر | Q18: حاضر | R18: غائب | S18: حاضر | T18: {=IF(ISNUMBER(MATCH(TRIM(A18)&"", _xlfn._xlws.FILTER(TRIM(Project_Scores!$D$2:$D$300)&"", Project_Scores!$I$2:$I$300=TRUE, ""), 0)), "حاضر", "غائب")} -> غائب | U18: =IF(COUNTA(O18:T18)=0,"0 من 0",COUNTIF(O18:T18,"حاضر")&" من "&COUNTA(O18:T18)) -> 4 من 6 | V18: =IF(COUNTA(O18:T18)=0,0,COUNTIF(O18:T18,"حاضر")/COUNTA(O18:T18)) -> 0.66666667 | W18: =M18+N18 -> 118 | X18: 148 | Y18: =COUNTIF(O18:T18,"حاضر") -> 4 | Z18: =COUNTA(O18:T18) -> 6 | AA18: =COUNTIF(O18:T18,"حاضر")+(COUNTIF(O18:T18,"مستأذن")*0.5)+X18 -> 152 | AC18: 20241701016 | AD18: يوسف سيد علي علي | AE18: 184.5
A19: 20251701124 | B19: Aly Mohamed Mounir Aly Zaky Darwish | C19: 20251701124 | D19: Level 1 | E19: General ( طلاب المستوى الأول والثاني خلال العام الدراسي السابق 25-26) | F19: 20251701124@cis.asu.edu.eg | G19: aly.mounirr@gmail.com | H19: 01226469696 | I19: عبدالله هاني محمد نصر الدين عبدالحق | J19: 53 | K19: 45 | L19: 39 | M19: =IF(COUNTA(J19:L19)=0,0,SUM(J19:L19)) -> 137 | N19: 30 | O19: حاضر | P19: حاضر | Q19: حاضر | R19: حاضر | S19: حاضر | T19: {=IF(ISNUMBER(MATCH(TRIM(A19)&"", _xlfn._xlws.FILTER(TRIM(Project_Scores!$D$2:$D$300)&"", Project_Scores!$I$2:$I$300=TRUE, ""), 0)), "حاضر", "غائب")} -> غائب | U19: =IF(COUNTA(O19:T19)=0,"0 من 0",COUNTIF(O19:T19,"حاضر")&" من "&COUNTA(O19:T19)) -> 5 من 6 | V19: =IF(COUNTA(O19:T19)=0,0,COUNTIF(O19:T19,"حاضر")/COUNTA(O19:T19)) -> 0.83333333 | W19: =M19+N19 -> 167 | X19: 207 | Y19: =COUNTIF(O19:T19,"حاضر") -> 5 | Z19: =COUNTA(O19:T19) -> 6 | AA19: =COUNTIF(O19:T19,"حاضر")+(COUNTIF(O19:T19,"مستأذن")*0.5)+X19 -> 212
A20: 20241700235 | B20: جيهان جواد محمد اليوسفي | C20: 20241700235 | D20: Level 1 | E20: General ( طلاب المستوى الأول والثاني خلال العام الدراسي السابق 25-26) | F20: 20241700235@cis.asu.edu.eg | G20: jih.an.jih.2000@gmail.com | H20: 01021838227 | I20: منة الله وحيد محمد على | J20: 55 | K20: 35 | L20: 0 | M20: =IF(COUNTA(J20:L20)=0,0,SUM(J20:L20)) -> 90 | N20: 0 | O20: حاضر | P20: غائب | Q20: حاضر | R20: حاضر | S20: حاضر | T20: {=IF(ISNUMBER(MATCH(TRIM(A20)&"", _xlfn._xlws.FILTER(TRIM(Project_Scores!$D$2:$D$300)&"", Project_Scores!$I$2:$I$300=TRUE, ""), 0)), "حاضر", "غائب")} -> غائب | U20: =IF(COUNTA(O20:T20)=0,"0 من 0",COUNTIF(O20:T20,"حاضر")&" من "&COUNTA(O20:T20)) -> 4 من 6 | V20: =IF(COUNTA(O20:T20)=0,0,COUNTIF(O20:T20,"حاضر")/COUNTA(O20:T20)) -> 0.66666667 | W20: =M20+N20 -> 90 | X20: 120 | Y20: =COUNTIF(O20:T20,"حاضر") -> 4 | Z20: =COUNTA(O20:T20) -> 6 | AA20: =COUNTIF(O20:T20,"حاضر")+(COUNTIF(O20:T20,"مستأذن")*0.5)+X20 -> 124
A21: 20241700174 | B21: بسملة فهيم حسنى سعيد | C21: 20241700174 | D21: Level 2 | E21: General ( طلاب المستوى الأول والثاني خلال العام الدراسي السابق 25-26) | F21: 20241700174@cis.asu.edu.eg | G21: basmalafahim42@gmail.com | H21: 01022315785 | I21: نانسي محمد جلال عباس | J21: 55 | K21: 45 | L21: 38 | M21: =IF(COUNTA(J21:L21)=0,0,SUM(J21:L21)) -> 138 | N21: 0 | O21: حاضر | P21: حاضر | Q21: حاضر | R21: حاضر | S21: حاضر | T21: {=IF(ISNUMBER(MATCH(TRIM(A21)&"", _xlfn._xlws.FILTER(TRIM(Project_Scores!$D$2:$D$300)&"", Project_Scores!$I$2:$I$300=TRUE, ""), 0)), "حاضر", "غائب")} -> غائب | U21: =IF(COUNTA(O21:T21)=0,"0 من 0",COUNTIF(O21:T21,"حاضر")&" من "&COUNTA(O21:T21)) -> 5 من 6 | V21: =IF(COUNTA(O21:T21)=0,0,COUNTIF(O21:T21,"حاضر")/COUNTA(O21:T21)) -> 0.83333333 | W21: =M21+N21 -> 138 | X21: 178 | Y21: =COUNTIF(O21:T21,"حاضر") -> 5 | Z21: =COUNTA(O21:T21) -> 6 | AA21: =COUNTIF(O21:T21,"حاضر")+(COUNTIF(O21:T21,"مستأذن")*0.5)+X21 -> 183
A22: 20241701015 | B22: يوسف سامى شعبان كامل | C22: 20241701015 | D22: Level 2 | E22: General ( طلاب المستوى الأول والثاني خلال العام الدراسي السابق 25-26) | F22: 20241701015@cis.asu.edu.eg | G22: ysamy6890@gmail.com | H22: 01117982889 | I22: عمر مصطفي سلامة علي | J22: 39 | K22: 40 | L22: 15 | M22: =IF(COUNTA(J22:L22)=0,0,SUM(J22:L22)) -> 94 | N22: 1 | O22: حاضر | P22: حاضر | Q22: حاضر | R22: حاضر | S22: حاضر | T22: {=IF(ISNUMBER(MATCH(TRIM(A22)&"", _xlfn._xlws.FILTER(TRIM(Project_Scores!$D$2:$D$300)&"", Project_Scores!$I$2:$I$300=TRUE, ""), 0)), "حاضر", "غائب")} -> غائب | U22: =IF(COUNTA(O22:T22)=0,"0 من 0",COUNTIF(O22:T22,"حاضر")&" من "&COUNTA(O22:T22)) -> 5 من 6 | V22: =IF(COUNTA(O22:T22)=0,0,COUNTIF(O22:T22,"حاضر")/COUNTA(O22:T22)) -> 0.83333333 | W22: =M22+N22 -> 95 | X22: 135 | Y22: =COUNTIF(O22:T22,"حاضر") -> 5 | Z22: =COUNTA(O22:T22) -> 6 | AA22: =COUNTIF(O22:T22,"حاضر")+(COUNTIF(O22:T22,"مستأذن")*0.5)+X22 -> 140
A23: 20241700590 | B23: عمرو خالد أحمد محمود | C23: 20241700590 | D23: Level 2 | E23: General ( طلاب المستوى الأول والثاني خلال العام الدراسي السابق 25-26) | F23: 20241700590@cis.asu.edu.eg | G23: amr.k.eltaweel@gmail.com | H23: 01002748249 | I23: نور جاد علي جاد | J23: 55 | K23: 37 | L23: 35 | M23: =IF(COUNTA(J23:L23)=0,0,SUM(J23:L23)) -> 127 | N23: 3 | O23: حاضر | P23: حاضر | Q23: حاضر | R23: مستأذن | S23: حاضر | T23: {=IF(ISNUMBER(MATCH(TRIM(A23)&"", _xlfn._xlws.FILTER(TRIM(Project_Scores!$D$2:$D$300)&"", Project_Scores!$I$2:$I$300=TRUE, ""), 0)), "حاضر", "غائب")} -> غائب | U23: =IF(COUNTA(O23:T23)=0,"0 من 0",COUNTIF(O23:T23,"حاضر")&" من "&COUNTA(O23:T23)) -> 4 من 6 | V23: =IF(COUNTA(O23:T23)=0,0,COUNTIF(O23:T23,"حاضر")/COUNTA(O23:T23)) -> 0.66666667 | W23: =M23+N23 -> 130 | X23: 160 | Y23: =COUNTIF(O23:T23,"حاضر") -> 4 | Z23: =COUNTA(O23:T23) -> 6 | AA23: =COUNTIF(O23:T23,"حاضر")+(COUNTIF(O23:T23,"مستأذن")*0.5)+X23 -> 164.5
A24: 20241700088 | B24: آدم احمد سمير إبراهيم | C24: 20241700088 | D24: Level 2 | E24: General ( طلاب المستوى الأول والثاني خلال العام الدراسي السابق 25-26) | F24: 20241700088@cis.asu.edu.eg | G24: adam.samir26220@gmail.com | H24: 01116979793 | I24: نانسي محمد جلال عباس | J24: 55 | K24: 38 | L24: 25 | M24: =IF(COUNTA(J24:L24)=0,0,SUM(J24:L24)) -> 118 | N24: 0 | O24: حاضر | P24: حاضر | Q24: حاضر | R24: حاضر | S24: حاضر | T24: {=IF(ISNUMBER(MATCH(TRIM(A24)&"", _xlfn._xlws.FILTER(TRIM(Project_Scores!$D$2:$D$300)&"", Project_Scores!$I$2:$I$300=TRUE, ""), 0)), "حاضر", "غائب")} -> غائب | U24: =IF(COUNTA(O24:T24)=0,"0 من 0",COUNTIF(O24:T24,"حاضر")&" من "&COUNTA(O24:T24)) -> 5 من 6 | V24: =IF(COUNTA(O24:T24)=0,0,COUNTIF(O24:T24,"حاضر")/COUNTA(O24:T24)) -> 0.83333333 | W24: =M24+N24 -> 118 | X24: 158 | Y24: =COUNTIF(O24:T24,"حاضر") -> 5 | Z24: =COUNTA(O24:T24) -> 6 | AA24: =COUNTIF(O24:T24,"حاضر")+(COUNTIF(O24:T24,"مستأذن")*0.5)+X24 -> 163
A25: 20241700049 | B25: احمد علي محمد علي حماده | C25: 20241700049 | D25: Level 2 | E25: General ( طلاب المستوى الأول والثاني خلال العام الدراسي السابق 25-26) | F25: 20241700049@cis.asu.edu.eg | G25: ahmed.thatha12@gmail.com | H25: 01110963213 | I25: عمر مصطفي سلامة علي | J25: 40 | K25: 40 | L25: 15 | M25: =IF(COUNTA(J25:L25)=0,0,SUM(J25:L25)) -> 95 | N25: 0 | O25: حاضر | P25: حاضر | Q25: حاضر | R25: غائب | S25: حاضر | T25: {=IF(ISNUMBER(MATCH(TRIM(A25)&"", _xlfn._xlws.FILTER(TRIM(Project_Scores!$D$2:$D$300)&"", Project_Scores!$I$2:$I$300=TRUE, ""), 0)), "حاضر", "غائب")} -> غائب | U25: =IF(COUNTA(O25:T25)=0,"0 من 0",COUNTIF(O25:T25,"حاضر")&" من "&COUNTA(O25:T25)) -> 4 من 6 | V25: =IF(COUNTA(O25:T25)=0,0,COUNTIF(O25:T25,"حاضر")/COUNTA(O25:T25)) -> 0.66666667 | W25: =M25+N25 -> 95 | X25: 125 | Y25: =COUNTIF(O25:T25,"حاضر") -> 4 | Z25: =COUNTA(O25:T25) -> 6 | AA25: =COUNTIF(O25:T25,"حاضر")+(COUNTIF(O25:T25,"مستأذن")*0.5)+X25 -> 129
A26: 20251701741 | B26: ملك حسين علي عبداللاه | C26: 20251701741 | D26: Level 1 | E26: SW Engineering | F26: 20251701741@cis.asu.edu.eg | G26: malakeltahan59@gmail.com | H26: 01062418859 | I26: منة الله وحيد محمد على | J26: 55 | K26: 32.5 | L26: 0 | M26: =IF(COUNTA(J26:L26)=0,0,SUM(J26:L26)) -> 87.5 | N26: 0 | O26: حاضر | P26: حاضر | Q26: حاضر | R26: حاضر | S26: حاضر | T26: {=IF(ISNUMBER(MATCH(TRIM(A26)&"", _xlfn._xlws.FILTER(TRIM(Project_Scores!$D$2:$D$300)&"", Project_Scores!$I$2:$I$300=TRUE, ""), 0)), "حاضر", "غائب")} -> غائب | U26: =IF(COUNTA(O26:T26)=0,"0 من 0",COUNTIF(O26:T26,"حاضر")&" من "&COUNTA(O26:T26)) -> 5 من 6 | V26: =IF(COUNTA(O26:T26)=0,0,COUNTIF(O26:T26,"حاضر")/COUNTA(O26:T26)) -> 0.83333333 | W26: =M26+N26 -> 87.5 | X26: 127.5 | Y26: =COUNTIF(O26:T26,"حاضر") -> 5 | Z26: =COUNTA(O26:T26) -> 6 | AA26: =COUNTIF(O26:T26,"حاضر")+(COUNTIF(O26:T26,"مستأذن")*0.5)+X26 -> 132.5
A27: 2023170051 | B27: احمد محمد احمد حفني | C27: 2023170051 | D27: Level 3 | E27: Scientific Computing | F27: 2023170051@cis.asu.edu.eg | G27: ahmedmohammmed875@gmail.com | H27: 01091841380 | I27: محمد طاهر محمد محمود | J27: 50 | K27: 30 | L27: 20 | M27: =IF(COUNTA(J27:L27)=0,0,SUM(J27:L27)) -> 100 | N27: 8 | O27: حاضر | P27: حاضر | Q27: حاضر | R27: حاضر | S27: غائب | T27: {=IF(ISNUMBER(MATCH(TRIM(A27)&"", _xlfn._xlws.FILTER(TRIM(Project_Scores!$D$2:$D$300)&"", Project_Scores!$I$2:$I$300=TRUE, ""), 0)), "حاضر", "غائب")} -> غائب | U27: =IF(COUNTA(O27:T27)=0,"0 من 0",COUNTIF(O27:T27,"حاضر")&" من "&COUNTA(O27:T27)) -> 4 من 6 | V27: =IF(COUNTA(O27:T27)=0,0,COUNTIF(O27:T27,"حاضر")/COUNTA(O27:T27)) -> 0.66666667 | W27: =M27+N27 -> 108 | X27: 148 | Y27: =COUNTIF(O27:T27,"حاضر") -> 4 | Z27: =COUNTA(O27:T27) -> 6 | AA27: =COUNTIF(O27:T27,"حاضر")+(COUNTIF(O27:T27,"مستأذن")*0.5)+X27 -> 152
A28: 20241700232 | B28: جون باسم وجدي وهيب | C28: 20241700232 | D28: Level 2 | E28: General ( طلاب المستوى الأول والثاني خلال العام الدراسي السابق 25-26) | F28: 20241700232@cis.asu.edu.eg | G28: johnbassem48@gmail.com | H28: 01289264131 | I28: عبدالرحمن احمد احمد سند | J28: 40 | K28: 25 | L28: 17 | M28: =IF(COUNTA(J28:L28)=0,0,SUM(J28:L28)) -> 82 | N28: 0 | O28: غائب | P28: حاضر | Q28: حاضر | R28: حاضر | S28: حاضر | T28: {=IF(ISNUMBER(MATCH(TRIM(A28)&"", _xlfn._xlws.FILTER(TRIM(Project_Scores!$D$2:$D$300)&"", Project_Scores!$I$2:$I$300=TRUE, ""), 0)), "حاضر", "غائب")} -> غائب | U28: =IF(COUNTA(O28:T28)=0,"0 من 0",COUNTIF(O28:T28,"حاضر")&" من "&COUNTA(O28:T28)) -> 4 من 6 | V28: =IF(COUNTA(O28:T28)=0,0,COUNTIF(O28:T28,"حاضر")/COUNTA(O28:T28)) -> 0.66666667 | W28: =M28+N28 -> 82 | X28: 112 | Y28: =COUNTIF(O28:T28,"حاضر") -> 4 | Z28: =COUNTA(O28:T28) -> 6 | AA28: =COUNTIF(O28:T28,"حاضر")+(COUNTIF(O28:T28,"مستأذن")*0.5)+X28 -> 116
A29: 20251700432 | B29: عبدالله كرم ابوزيد سيف | C29: 20251700432 | D29: Level 1 | E29: General ( طلاب المستوى الأول والثاني خلال العام الدراسي السابق 25-26) | F29: 20251700432@cis.asu.edu.eg | G29: abduallahkaram301@gmail.com | H29: 01093493111 | I29: ياسمين صلاح الدين عباس | J29: 50.5 | K29: 37 | L29: 35 | M29: =IF(COUNTA(J29:L29)=0,0,SUM(J29:L29)) -> 122.5 | N29: 29 | O29: حاضر | P29: حاضر | Q29: حاضر | R29: حاضر | S29: حاضر | T29: {=IF(ISNUMBER(MATCH(TRIM(A29)&"", _xlfn._xlws.FILTER(TRIM(Project_Scores!$D$2:$D$300)&"", Project_Scores!$I$2:$I$300=TRUE, ""), 0)), "حاضر", "غائب")} -> غائب | U29: =IF(COUNTA(O29:T29)=0,"0 من 0",COUNTIF(O29:T29,"حاضر")&" من "&COUNTA(O29:T29)) -> 5 من 6 | V29: =IF(COUNTA(O29:T29)=0,0,COUNTIF(O29:T29,"حاضر")/COUNTA(O29:T29)) -> 0.83333333 | W29: =M29+N29 -> 151.5 | X29: 191.5 | Y29: =COUNTIF(O29:T29,"حاضر") -> 5 | Z29: =COUNTA(O29:T29) -> 6 | AA29: =COUNTIF(O29:T29,"حاضر")+(COUNTIF(O29:T29,"مستأذن")*0.5)+X29 -> 196.5
A30: 20241700219 | B30: جنى ناصر محمد ذكى | C30: 20241700219 | D30: Level 2 | E30: General ( طلاب المستوى الأول والثاني خلال العام الدراسي السابق 25-26) | F30: 20241700219@cis.asu.edu.eg | G30: nasserjana671@gmail.com | H30: 01157158146 | I30: منة الله وحيد محمد على | J30: 54 | K30: 25 | L30: 21 | M30: =IF(COUNTA(J30:L30)=0,0,SUM(J30:L30)) -> 100 | N30: 0 | O30: حاضر | P30: مستأذن | Q30: حاضر | R30: حاضر | S30: حاضر | T30: {=IF(ISNUMBER(MATCH(TRIM(A30)&"", _xlfn._xlws.FILTER(TRIM(Project_Scores!$D$2:$D$300)&"", Project_Scores!$I$2:$I$300=TRUE, ""), 0)), "حاضر", "غائب")} -> غائب | U30: =IF(COUNTA(O30:T30)=0,"0 من 0",COUNTIF(O30:T30,"حاضر")&" من "&COUNTA(O30:T30)) -> 4 من 6 | V30: =IF(COUNTA(O30:T30)=0,0,COUNTIF(O30:T30,"حاضر")/COUNTA(O30:T30)) -> 0.66666667 | W30: =M30+N30 -> 100 | X30: 130 | Y30: =COUNTIF(O30:T30,"حاضر") -> 4 | Z30: =COUNTA(O30:T30) -> 6 | AA30: =COUNTIF(O30:T30,"حاضر")+(COUNTIF(O30:T30,"مستأذن")*0.5)+X30 -> 134.5
... A44: 20241700920 | B44: ندى محمود رياض نور الدين محمود | C44: 20241700920 | D44: Level 2 | E44: General ( طلاب المستوى الأول والثاني خلال العام الدراسي السابق 25-26) | F44: 20241700920@cis.asu.edu.eg | G44: nmr111006@gmail.com | H44: 01017817373 | I44: عبدالله هاني محمد نصر الدين عبدالحق | J44: 55 | K44: 45 | L44: 39 | M44: =IF(COUNTA(J44:L44)=0,0,SUM(J44:L44)) -> 139 | N44: 15 | O44: حاضر | P44: حاضر | Q44: حاضر | R44: حاضر | S44: حاضر | T44: {=IF(ISNUMBER(MATCH(TRIM(A44)&"", _xlfn._xlws.FILTER(TRIM(Project_Scores!$D$2:$D$300)&"", Project_Scores!$I$2:$I$300=TRUE, ""), 0)), "حاضر", "غائب")} -> غائب | U44: =IF(COUNTA(O44:T44)=0,"0 من 0",COUNTIF(O44:T44,"حاضر")&" من "&COUNTA(O44:T44)) -> 5 من 6 | V44: =IF(COUNTA(O44:T44)=0,0,COUNTIF(O44:T44,"حاضر")/COUNTA(O44:T44)) -> 0.83333333 | W44: =M44+N44 -> 154 | X44: 194 | Y44: =COUNTIF(O44:T44,"حاضر") -> 5 | Z44: =COUNTA(O44:T44) -> 6 | AA44: =COUNTIF(O44:T44,"حاضر")+(COUNTIF(O44:T44,"مستأذن")*0.5)+X44 -> 199
A45: 20251700025 | B45: احمد سالم السيد سليمان | C45: 20251700025 | D45: Level 1 | E45: General ( طلاب المستوى الأول والثاني خلال العام الدراسي السابق 25-26) | F45: 20251700025@cis.asu.edu.eg | G45: as2405897@gmail.com | H45: 01200690946 | I45: احمد اسماعيل سيد محمدي | J45: 54 | K45: 31 | L45: 15 | M45: =IF(COUNTA(J45:L45)=0,0,SUM(J45:L45)) -> 100 | N45: 8 | O45: حاضر | P45: حاضر | Q45: حاضر | R45: حاضر | S45: حاضر | T45: {=IF(ISNUMBER(MATCH(TRIM(A45)&"", _xlfn._xlws.FILTER(TRIM(Project_Scores!$D$2:$D$300)&"", Project_Scores!$I$2:$I$300=TRUE, ""), 0)), "حاضر", "غائب")} -> غائب | U45: =IF(COUNTA(O45:T45)=0,"0 من 0",COUNTIF(O45:T45,"حاضر")&" من "&COUNTA(O45:T45)) -> 5 من 6 | V45: =IF(COUNTA(O45:T45)=0,0,COUNTIF(O45:T45,"حاضر")/COUNTA(O45:T45)) -> 0.83333333 | W45: =M45+N45 -> 108 | X45: 148 | Y45: =COUNTIF(O45:T45,"حاضر") -> 5 | Z45: =COUNTA(O45:T45) -> 6 | AA45: =COUNTIF(O45:T45,"حاضر")+(COUNTIF(O45:T45,"مستأذن")*0.5)+X45 -> 153 | AC45: =COUNTIF(T:T, "حاضر") -> 0
A46: 20241700935 | B46: نوران محمد السيد محمد نصر | C46: 20241700935 | D46: Level 2 | E46: General ( طلاب المستوى الأول والثاني خلال العام الدراسي السابق 25-26) | F46: 20241700935@cis.asu.edu.eg | G46: nouran3367@gmail.com | H46: 01280841784 | I46: 3bdullah | J46: 55 | K46: 45 | L46: 37 | M46: =IF(COUNTA(J46:L46)=0,0,SUM(J46:L46)) -> 137 | N46: 8 | O46: حاضر | P46: حاضر | Q46: حاضر | R46: حاضر | S46: حاضر | T46: {=IF(ISNUMBER(MATCH(TRIM(A46)&"", _xlfn._xlws.FILTER(TRIM(Project_Scores!$D$2:$D$300)&"", Project_Scores!$I$2:$I$300=TRUE, ""), 0)), "حاضر", "غائب")} -> غائب | U46: =IF(COUNTA(O46:T46)=0,"0 من 0",COUNTIF(O46:T46,"حاضر")&" من "&COUNTA(O46:T46)) -> 5 من 6 | V46: =IF(COUNTA(O46:T46)=0,0,COUNTIF(O46:T46,"حاضر")/COUNTA(O46:T46)) -> 0.83333333 | W46: =M46+N46 -> 145 | X46: 185 | Y46: =COUNTIF(O46:T46,"حاضر") -> 5 | Z46: =COUNTA(O46:T46) -> 6 | AA46: =COUNTIF(O46:T46,"حاضر")+(COUNTIF(O46:T46,"مستأذن")*0.5)+X46 -> 190
A47: 2023170326 | B47: عبدالله يسرى ثابت عبدالرحمن | C47: 2023170326 | D47: Level 3 | E47: Information Systems | F47: 2023170326@cis.asu.edu.eg | G47: youserythabet@gmail.com | H47: 01158777563 | I47: ياسمين صلاح الدين عباس | J47: 40 | K47: 43 | L47: 0 | M47: =IF(COUNTA(J47:L47)=0,0,SUM(J47:L47)) -> 83 | N47: 16 | O47: حاضر | P47: حاضر | Q47: حاضر | R47: حاضر | S47: حاضر | T47: {=IF(ISNUMBER(MATCH(TRIM(A47)&"", _xlfn._xlws.FILTER(TRIM(Project_Scores!$D$2:$D$300)&"", Project_Scores!$I$2:$I$300=TRUE, ""), 0)), "حاضر", "غائب")} -> غائب | U47: =IF(COUNTA(O47:T47)=0,"0 من 0",COUNTIF(O47:T47,"حاضر")&" من "&COUNTA(O47:T47)) -> 5 من 6 | V47: =IF(COUNTA(O47:T47)=0,0,COUNTIF(O47:T47,"حاضر")/COUNTA(O47:T47)) -> 0.83333333 | W47: =M47+N47 -> 99 | X47: 139 | Y47: =COUNTIF(O47:T47,"حاضر") -> 5 | Z47: =COUNTA(O47:T47) -> 6 | AA47: =COUNTIF(O47:T47,"حاضر")+(COUNTIF(O47:T47,"مستأذن")*0.5)+X47 -> 144
A48: 20231700213 | B48: تقى حسنى محمود محمد | C48: 20231700213 | D48: Level 3 | E48: Artificial Intelligence | F48: 20231700213@cis.asu.edu.eg | G48: tokahosnyy@gmail.com | H48: 01555931607 | I48: منة الله وحيد محمد على | J48: 55 | K48: 37.5 | L48: 36 | M48: =IF(COUNTA(J48:L48)=0,0,SUM(J48:L48)) -> 128.5 | N48: 0 | O48: حاضر | P48: حاضر | Q48: حاضر | R48: غائب | S48: غائب | T48: {=IF(ISNUMBER(MATCH(TRIM(A48)&"", _xlfn._xlws.FILTER(TRIM(Project_Scores!$D$2:$D$300)&"", Project_Scores!$I$2:$I$300=TRUE, ""), 0)), "حاضر", "غائب")} -> غائب | U48: =IF(COUNTA(O48:T48)=0,"0 من 0",COUNTIF(O48:T48,"حاضر")&" من "&COUNTA(O48:T48)) -> 3 من 6 | V48: =IF(COUNTA(O48:T48)=0,0,COUNTIF(O48:T48,"حاضر")/COUNTA(O48:T48)) -> 0.5 | W48: =M48+N48 -> 128.5 | X48: 158.5 | Y48: =COUNTIF(O48:T48,"حاضر") -> 3 | Z48: =COUNTA(O48:T48) -> 6 | AA48: =COUNTIF(O48:T48,"حاضر")+(COUNTIF(O48:T48,"مستأذن")*0.5)+X48 -> 161.5
A49: 20241700208 | B49: جمال حسام الدين مصطفى | C49: 20241700208 | D49: Level 2 | E49: General ( طلاب المستوى الأول والثاني خلال العام الدراسي السابق 25-26) | F49: 20241700208@cis.asu.edu.eg | G49: ghossam.618979@gmail.com | H49: 01155384335 | I49: نانسي محمد جلال عباس | J49: 38 | K49: 40 | L49: 20 | M49: =IF(COUNTA(J49:L49)=0,0,SUM(J49:L49)) -> 98 | N49: 12 | O49: حاضر | P49: حاضر | Q49: حاضر | R49: حاضر | S49: غائب | T49: {=IF(ISNUMBER(MATCH(TRIM(A49)&"", _xlfn._xlws.FILTER(TRIM(Project_Scores!$D$2:$D$300)&"", Project_Scores!$I$2:$I$300=TRUE, ""), 0)), "حاضر", "غائب")} -> غائب | U49: =IF(COUNTA(O49:T49)=0,"0 من 0",COUNTIF(O49:T49,"حاضر")&" من "&COUNTA(O49:T49)) -> 4 من 6 | V49: =IF(COUNTA(O49:T49)=0,0,COUNTIF(O49:T49,"حاضر")/COUNTA(O49:T49)) -> 0.66666667 | W49: =M49+N49 -> 110 | X49: 150 | Y49: =COUNTIF(O49:T49,"حاضر") -> 4 | Z49: =COUNTA(O49:T49) -> 6 | AA49: =COUNTIF(O49:T49,"حاضر")+(COUNTIF(O49:T49,"مستأذن")*0.5)+X49 -> 154
A50: 20231700233 | B50: علي عمرو محمد عبدالهادي | C50: 20231700233 | D50: Level 3 | E50: Artificial Intelligence | F50: 20231700233@cis.asu.edu.eg | G50: oppoa31omar@gmail.com | H50: 01066973048 | I50: اسراء محمود | J50: 55 | K50: 45 | L50: 40 | M50: =IF(COUNTA(J50:L50)=0,0,SUM(J50:L50)) -> 140 | N50: 6 | O50: حاضر | P50: حاضر | Q50: حاضر | R50: حاضر | S50: حاضر | T50: {=IF(ISNUMBER(MATCH(TRIM(A50)&"", _xlfn._xlws.FILTER(TRIM(Project_Scores!$D$2:$D$300)&"", Project_Scores!$I$2:$I$300=TRUE, ""), 0)), "حاضر", "غائب")} -> غائب | U50: =IF(COUNTA(O50:T50)=0,"0 من 0",COUNTIF(O50:T50,"حاضر")&" من "&COUNTA(O50:T50)) -> 5 من 6 | V50: =IF(COUNTA(O50:T50)=0,0,COUNTIF(O50:T50,"حاضر")/COUNTA(O50:T50)) -> 0.83333333 | W50: =M50+N50 -> 146 | X50: 186 | Y50: =COUNTIF(O50:T50,"حاضر") -> 5 | Z50: =COUNTA(O50:T50) -> 6 | AA50: =COUNTIF(O50:T50,"حاضر")+(COUNTIF(O50:T50,"مستأذن")*0.5)+X50 -> 191
A51: 2023170065 | B51: احمد نبيل عبدالرحمن عبدالرحمن | C51: 2023170065 | D51: Level 3 | E51: Information Systems | F51: 2023170065@cis.asu.edu.eg | G51: nabilion987@gmail.com | H51: 01017599487 | I51: اسراء محمود | J51: 0 | K51: 0 | L51: 0 | M51: =IF(COUNTA(J51:L51)=0,0,SUM(J51:L51)) -> 0 | N51: 5 | O51: حاضر | P51: حاضر | Q51: حاضر | R51: حاضر | S51: حاضر | T51: {=IF(ISNUMBER(MATCH(TRIM(A51)&"", _xlfn._xlws.FILTER(TRIM(Project_Scores!$D$2:$D$300)&"", Project_Scores!$I$2:$I$300=TRUE, ""), 0)), "حاضر", "غائب")} -> غائب | U51: =IF(COUNTA(O51:T51)=0,"0 من 0",COUNTIF(O51:T51,"حاضر")&" من "&COUNTA(O51:T51)) -> 5 من 6 | V51: =IF(COUNTA(O51:T51)=0,0,COUNTIF(O51:T51,"حاضر")/COUNTA(O51:T51)) -> 0.83333333 | W51: =M51+N51 -> 5 | X51: 45 | Y51: =COUNTIF(O51:T51,"حاضر") -> 5 | Z51: =COUNTA(O51:T51) -> 6 | AA51: =COUNTIF(O51:T51,"حاضر")+(COUNTIF(O51:T51,"مستأذن")*0.5)+X51 -> 50
A52: 2023170597 | B52: مشكاة النعمان احمد عمر | C52: 2023170597 | D52: Level 3 | E52: Scientific Computing | F52: 2023170597@cis.asu.edu.eg | G52: m15.1234567fg@gmail.com | H52: 01124125633 | I52: عبدالرحمن احمد احمد سند | J52: 39 | K52: 25 | L52: 15 | M52: =IF(COUNTA(J52:L52)=0,0,SUM(J52:L52)) -> 79 | N52: 0 | O52: حاضر | P52: مستأذن | Q52: حاضر | R52: حاضر | S52: حاضر | T52: {=IF(ISNUMBER(MATCH(TRIM(A52)&"", _xlfn._xlws.FILTER(TRIM(Project_Scores!$D$2:$D$300)&"", Project_Scores!$I$2:$I$300=TRUE, ""), 0)), "حاضر", "غائب")} -> غائب | U52: =IF(COUNTA(O52:T52)=0,"0 من 0",COUNTIF(O52:T52,"حاضر")&" من "&COUNTA(O52:T52)) -> 4 من 6 | V52: =IF(COUNTA(O52:T52)=0,0,COUNTIF(O52:T52,"حاضر")/COUNTA(O52:T52)) -> 0.66666667 | W52: =M52+N52 -> 79 | X52: 109 | Y52: =COUNTIF(O52:T52,"حاضر") -> 4 | Z52: =COUNTA(O52:T52) -> 6 | AA52: =COUNTIF(O52:T52,"حاضر")+(COUNTIF(O52:T52,"مستأذن")*0.5)+X52 -> 113.5
A53: 20241700770 | B53: محمد يوسف عباس مرسي | C53: 20241700770 | D53: Level 2 | E53: General ( طلاب المستوى الأول والثاني خلال العام الدراسي السابق 25-26) | F53: 20241700770@cis.asu.edu.eg | G53: mohamedyoussef22328@gmail.com | H53: 01122556021 | I53: عبدالرحمن احمد احمد سند | J53: 40 | K53: 25 | L53: 15 | M53: =IF(COUNTA(J53:L53)=0,0,SUM(J53:L53)) -> 80 | N53: 0 | O53: حاضر | P53: حاضر | Q53: حاضر | R53: حاضر | S53: حاضر | T53: {=IF(ISNUMBER(MATCH(TRIM(A53)&"", _xlfn._xlws.FILTER(TRIM(Project_Scores!$D$2:$D$300)&"", Project_Scores!$I$2:$I$300=TRUE, ""), 0)), "حاضر", "غائب")} -> غائب | U53: =IF(COUNTA(O53:T53)=0,"0 من 0",COUNTIF(O53:T53,"حاضر")&" من "&COUNTA(O53:T53)) -> 5 من 6 | V53: =IF(COUNTA(O53:T53)=0,0,COUNTIF(O53:T53,"حاضر")/COUNTA(O53:T53)) -> 0.83333333 | W53: =M53+N53 -> 80 | X53: 120 | Y53: =COUNTIF(O53:T53,"حاضر") -> 5 | Z53: =COUNTA(O53:T53) -> 6 | AA53: =COUNTIF(O53:T53,"حاضر")+(COUNTIF(O53:T53,"مستأذن")*0.5)+X53 -> 125
A54: 20251700271 | B54: رنا صبحي متولي حسن | C54: 20251700271 | D54: Level 1 | E54: General ( طلاب المستوى الأول والثاني خلال العام الدراسي السابق 25-26) | F54: 20251700271@cis.asu.edu.eg | G54: ranasobhy112007@gmail.com | H54: 01092850291 | I54: 3bdullah | J54: 50 | K54: 40 | L54: 35 | M54: =IF(COUNTA(J54:L54)=0,0,SUM(J54:L54)) -> 125 | N54: 6 | O54: حاضر | P54: حاضر | Q54: حاضر | R54: حاضر | S54: حاضر | T54: {=IF(ISNUMBER(MATCH(TRIM(A54)&"", _xlfn._xlws.FILTER(TRIM(Project_Scores!$D$2:$D$300)&"", Project_Scores!$I$2:$I$300=TRUE, ""), 0)), "حاضر", "غائب")} -> غائب | U54: =IF(COUNTA(O54:T54)=0,"0 من 0",COUNTIF(O54:T54,"حاضر")&" من "&COUNTA(O54:T54)) -> 5 من 6 | V54: =IF(COUNTA(O54:T54)=0,0,COUNTIF(O54:T54,"حاضر")/COUNTA(O54:T54)) -> 0.83333333 | W54: =M54+N54 -> 131 | X54: 171 | Y54: =COUNTIF(O54:T54,"حاضر") -> 5 | Z54: =COUNTA(O54:T54) -> 6 | AA54: =COUNTIF(O54:T54,"حاضر")+(COUNTIF(O54:T54,"مستأذن")*0.5)+X54 -> 176
...

Sheet Project_Scores
A1: Team | B1: No. | C1: Student Name | D1: Student ID | E1: Individual Score (max 40) | F1: Full Project Score (max 80) | G1: Project Bonus (max 25) | H1: Total Project Score (max 145) | I1: Attendance
A2: team 1 | B2: 1 | C2: رنا صبحي متولي | D2: 20251700271 | E2: 0 | H2: =IF(OR(E2="",F2="",G2=""),"",E2+F2+G2) | I2: FALSE
B3: 2 | C3: مرام ياسر على السيد | D3: 20251700766 | H3: =IF(OR(E3="",F2="",G2=""),"",E3+F2+G2) | I3: FALSE
B4: 3 | C4: مريم ياسر علي السيد | D4: 20251700797 | H4: =IF(OR(E4="",F2="",G2=""),"",E4+F2+G2) | I4: FALSE
B5: 4 | C5: فاطمة سامي محمد احمد | D5: 20251700575 | H5: =IF(OR(E5="",F2="",G2=""),"",E5+F2+G2) | I5: FALSE
B6: 5 | C6: رؤى البدرى السيد توفيق | D6: 20251700257 | H6: =IF(OR(E6="",F2="",G2=""),"",E6+F2+G2) | I6: FALSE
A7: team 2 | B7: 1 | C7: ياسمين حسام عادل حسانين | D7: 20251701139 | H7: =IF(OR(E7="",F7="",G7=""),"",E7+F7+G7) | I7: FALSE
B8: 2 | C8: سما عباس سيد يوسف | D8: 20251700360 | H8: =IF(OR(E8="",F7="",G7=""),"",E8+F7+G7) | I8: FALSE
B9: 3 | C9: اسماء احمد عزت عبدالمطلب | D9: 20251700097 | H9: =IF(OR(E9="",F7="",G7=""),"",E9+F7+G7) | I9: FALSE
B10: 4 | C10: عمر ايمن بدر | D10: 20251700511 | H10: =IF(OR(E10="",F7="",G7=""),"",E10+F7+G7) | I10: FALSE
B11: 5 | C11: عمر احمد محمد إسماعيل | D11: 20251700500 | H11: =IF(OR(E11="",F7="",G7=""),"",E11+F7+G7) | I11: FALSE
A12: team 3 | B12: 1 | C12: محمود محمد عبد الرسول كريم محمود | D12: 20251700762 | H12: =IF(OR(E12="",F12="",G12=""),"",E12+F12+G12) | I12: FALSE
B13: 2 | C13: أحمد سالم السيد سليمان ربيع | D13: 20251700025 | H13: =IF(OR(E13="",F12="",G12=""),"",E13+F12+G12) | I13: FALSE
B14: 3 | C14: محمود طه أحمد محمد سيد | D14: 20251700758 | H14: =IF(OR(E14="",F12="",G12=""),"",E14+F12+G12) | I14: FALSE
B15: 4 | C15: عمر سعيد إسماعيل السيد فروح | D15: 20251700521 | H15: =IF(OR(E15="",F12="",G12=""),"",E15+F12+G12) | I15: FALSE
B16: 5 | C16: ملك حسين علي عبداللاه | D16: 20251701741 | H16: =IF(OR(E16="",F12="",G12=""),"",E16+F12+G12) | I16: FALSE
A17: team 4 | B17: 1 | C17: عل محمد منير علي زكي | D17: 20251701124 | H17: =IF(OR(E17="",F17="",G17=""),"",E17+F17+G17) | I17: FALSE
B18: 2 | C18: عبدالله كرم ابوزيد سيف | D18: 20251700432 | H18: =IF(OR(E18="",F17="",G17=""),"",E18+F17+G17) | I18: FALSE
B19: 3 | C19: بيشوي امجد فوزي عبدالملاك | D19: 2023170147 | H19: =IF(OR(E19="",F17="",G17=""),"",E19+F17+G17) | I19: FALSE
B20: 4 | C20: معاذ هاني عبدالستار عبدالحليم | D20: 20251701090 | H20: =IF(OR(E20="",F17="",G17=""),"",E20+F17+G17) | I20: FALSE
B21: 5 | C21: بيشوي كرم اسعد ذكي | D21: 2023170149 | H21: =IF(OR(E21="",F17="",G17=""),"",E21+F17+G17) | I21: FALSE
A22: team 5 | B22: 1 | C22: محممود أحمد رأفت | D22: 20251700750 | H22: =IF(OR(E22="",F22="",G22=""),"",E22+F22+G22) | I22: FALSE
B23: 2 | C23: آيه محمد أداره | D23: 20251701037 | H23: =IF(OR(E23="",F22="",G22=""),"",E23+F22+G22) | I23: FALSE
B24: 3 | C24: رضوي علاء الدين | D24: 20251700264 | H24: =IF(OR(E24="",F22="",G22=""),"",E24+F22+G22) | I24: FALSE
B25: 4 | C25: مروان خالد عبد الجواد | D25: 20251700769 | H25: =IF(OR(E25="",F22="",G22=""),"",E25+F22+G22) | I25: FALSE
B26: 5 | C26: معاذ محمد عبد النبي | D26: 20251700824 | H26: =IF(OR(E26="",F22="",G22=""),"",E26+F22+G22) | I26: FALSE
A27: team 6 | B27: 1 | C27: ماريا بولس ابراهيم | D27: 20241700670 | H27: =IF(OR(E27="",F27="",G27=""),"",E27+F27+G27) | I27: FALSE
B28: 2 | C28: يوأنا ريمون منير | D28: 20241700995 | H28: =IF(OR(E28="",F27="",G27=""),"",E28+F27+G27) | I28: FALSE
B29: 3 | C29: جورج جمال عبده | D29: 20241700225 | H29: =IF(OR(E29="",F27="",G27=""),"",E29+F27+G27) | I29: FALSE
B30: 4 | C30: جون باسم وجدى | D30: 20241700232 | H30: =IF(OR(E30="",F27="",G27=""),"",E30+F27+G27) | I30: FALSE
B31: 5 | C31: جمال حسام الدين مصطفى | D31: 20241700208 | H31: =IF(OR(E31="",F27="",G27=""),"",E31+F27+G27) | I31: FALSE
A32: team 7 | B32: 1 | C32: فيرونيكا امير رفعت جاد | D32: 20251700588 | H32: =IF(OR(E32="",F32="",G32=""),"",E32+F32+G32) | I32: FALSE
B33: 2 | C33: سما عمرو عبد الرحمن سعد | D33: 20251701172 | H33: =IF(OR(E33="",F32="",G32=""),"",E33+F32+G32) | I33: FALSE
B34: 3 | C34: سارة نسيم عزيز اسعد | D34: 20251700328 | H34: =IF(OR(E34="",F32="",G32=""),"",E34+F32+G32) | I34: FALSE
B35: 4 | C35: الاء عماد احمد محمد | D35: 20251700104 | H35: =IF(OR(E35="",F32="",G32=""),"",E35+F32+G32) | I35: FALSE
B36: 5 | C36: ملك محمد احمد يس | D36: 20251701092 | H36: =IF(OR(E36="",F32="",G32=""),"",E36+F32+G32) | I36: FALSE
A37: team 8 | B37: 1 | C37: آدم محمد عطيتو السيد | D37: 20241700089 | H37: =IF(OR(E37="",F37="",G37=""),"",E37+F37+G37) | I37: FALSE
B38: 2 | C38: سعيد مسعد سعيد محمد | D38: 20241700374 | H38: =IF(OR(E38="",F37="",G37=""),"",E38+F37+G37) | I38: FALSE
B39: 3 | C39: عمرو محمد مصطفي محمد | D39: 20241700600 | H39: =IF(OR(E39="",F37="",G37=""),"",E39+F37+G37) | I39: FALSE
B40: 4 | C40: بوش عماد جمال جاد | D40: 20241700196 | H40: =IF(OR(E40="",F37="",G37=""),"",E40+F37+G37) | I40: FALSE
...

Sheet Project_Teams
A1: Team | B1: No. | C1: Student Name | D1: Student ID | E1: Academic Level | F1: Program | G1: Mobile Number | H1: University Email | I1: Supporter | J1: Individual Score (max 40) | K1: Full Project Score (max 80) | L1: Project Bonus (max 25) | M1: Total Project Score (max 145) | N1: Tasks Score (max 135) | O1: Attendance Rate (%) | P1: Attendance Score (out of sessions×20) | Q1: Tasks % | R1: Attendance % | S1: Project % | T1: Final Grade % | U1: Attendance ≥60%? | V1: Success Status
A2: team 1 | B2: 1 | C2: رنا صبحي متولي | D2: 20251700271 | E2: المستوى الأول/ Level 1 | F2: General (Mainstream) / عام | G2: 01092850291 | H2: 20251700271@cis.asu.edu.eg | I2: Nancy Mohamed | J2: =IFERROR(_xlfn.XLOOKUP(D2, Project_Scores!$D:$D, Project_Scores!$E:$E, 0), 0) -> 0 | K2: =IFERROR(_xlfn.XLOOKUP(D2, Project_Scores!$D:$D, Project_Scores!$F:$F, 0), 0) -> 0 | L2: =IFERROR(_xlfn.XLOOKUP(D2, Project_Scores!$D:$D, Project_Scores!$G:$G, 0), 0) -> 0 | M2: =SUM(K2,L2,J2) -> 0 | N2: =IFERROR(VLOOKUP(D2,Source_Grades!$A:$N,13,FALSE()),0) -> 125 | O2: =IFERROR(VLOOKUP(D2,Source_Grades!$A:$V,22,FALSE())*100,0) -> 83.333333 | P2: =IFERROR(VLOOKUP(D2,Source_Grades!$A:$Z,25,FALSE())*20,0) -> 100 | Q2: =IF(N2=0,0,N2/135*100) -> 92.592593 | R2: =O2 -> 83.333333 | S2: =IF(M2="",0,M2/145*100) -> 0 | T2: =Q2*0.2 + R2*0.3 + S2*0.5 -> 43.518519 | U2: =IF(R2>=60,"نعم","لا") -> نعم | V2: =IF(AND(T2>60,R2>=60),"ناجح","لم ينجح") -> لم ينجح
B3: 2 | C3: مرام ياسر على السيد | D3: 20251700766 | E3: المستوى الأول/ Level 1 | F3: General (Mainstream) / عام | G3: +20 11 28972875 | H3: 20251700766@cis.asu.edu.eg | J3: 0 | M3: =SUM(J3,K3,L3) -> 0 | N3: =IFERROR(VLOOKUP(D3,Source_Grades!$A:$N,13,FALSE()),0) -> 123 | O3: =IFERROR(VLOOKUP(D3,Source_Grades!$A:$V,22,FALSE())*100,0) -> 83.333333 | P3: =IFERROR(VLOOKUP(D3,Source_Grades!$A:$Z,25,FALSE())*20,0) -> 100 | Q3: =IF(N3=0,0,N3/135*100) -> 91.111111 | R3: =O3 -> 83.333333 | S3: =IF(M3="",0,M3/145*100) -> 0 | T3: =Q3*0.2 + R3*0.3 + S3*0.5 -> 43.222222 | U3: =IF(R3>=60,"نعم","لا") -> نعم | V3: =IF(AND(T3>60,R3>=60),"ناجح","لم ينجح") -> لم ينجح | AA3: Score board (top10)
B4: 3 | C4: مريم ياسر علي السيد | D4: 20251700797 | E4: المستوى الأول/ Level 1 | F4: General (Mainstream) / عام | G4: +20 10 01153283 | H4: 20251700797@cis.asu.edu.eg | J4: 0 | M4: =SUM(J4,K4,L4) -> 0 | N4: =IFERROR(VLOOKUP(D4,Source_Grades!$A:$N,13,FALSE()),0) -> 105 | O4: =IFERROR(VLOOKUP(D4,Source_Grades!$A:$V,22,FALSE())*100,0) -> 83.333333 | P4: =IFERROR(VLOOKUP(D4,Source_Grades!$A:$Z,25,FALSE())*20,0) -> 100 | Q4: =IF(N4=0,0,N4/135*100) -> 77.777778 | R4: =O4 -> 83.333333 | S4: =IF(M4="",0,M4/145*100) -> 0 | T4: =Q4*0.2 + R4*0.3 + S4*0.5 -> 40.555556 | U4: =IF(R4>=60,"نعم","لا") -> نعم | V4: =IF(AND(T4>60,R4>=60),"ناجح","لم ينجح") -> لم ينجح
B5: 4 | C5: فاطمة سامي محمد احمد | D5: 20251700575 | E5: المستوى الأول/ Level 1 | F5: General (Mainstream) / عام | G5: +20 11 43693735 | H5: 20251700575@cis.asu.edu.eg | J5: 0 | M5: =SUM(J5,K5,L5) -> 0 | N5: =IFERROR(VLOOKUP(D5,Source_Grades!$A:$N,13,FALSE()),0) -> 103 | O5: =IFERROR(VLOOKUP(D5,Source_Grades!$A:$V,22,FALSE())*100,0) -> 66.666667 | P5: =IFERROR(VLOOKUP(D5,Source_Grades!$A:$Z,25,FALSE())*20,0) -> 80 | Q5: =IF(N5=0,0,N5/135*100) -> 76.296296 | R5: =O5 -> 66.666667 | S5: =IF(M5="",0,M5/145*100) -> 0 | T5: =Q5*0.2 + R5*0.3 + S5*0.5 -> 35.259259 | U5: =IF(R5>=60,"نعم","لا") -> نعم | V5: =IF(AND(T5>60,R5>=60),"ناجح","لم ينجح") -> لم ينجح | AA5: Leader ID | AB5: Supporter name | AC5: Project Score | AD5: Team member Individual socre
B6: 5 | C6: رؤى البدرى السيد توفيق | D6: 20251700257 | E6: المستوى الأول/ Level 1 | F6: General (Mainstream) / عام | G6: 01140159717 | H6: 20251700257@cis.asu.edu.eg | J6: 0 | M6: =SUM(J6,K6,L6) -> 0 | N6: =IFERROR(VLOOKUP(D6,Source_Grades!$A:$N,13,FALSE()),0) -> 106 | O6: =IFERROR(VLOOKUP(D6,Source_Grades!$A:$V,22,FALSE())*100,0) -> 83.333333 | P6: =IFERROR(VLOOKUP(D6,Source_Grades!$A:$Z,25,FALSE())*20,0) -> 100 | Q6: =IF(N6=0,0,N6/135*100) -> 78.518519 | R6: =O6 -> 83.333333 | S6: =IF(M6="",0,M6/145*100) -> 0 | T6: =Q6*0.2 + R6*0.3 + S6*0.5 -> 40.703704 | U6: =IF(R6>=60,"نعم","لا") -> نعم | V6: =IF(AND(T6>60,R6>=60),"ناجح","لم ينجح") -> لم ينجح | AA6: {=_xlfn.LET(_xlpm.valid_rows, _xlfn._xlws.FILTER(ROW(2:300), A2:A300<>""), _xlpm.leader_ids, INDEX(D:D, _xlpm.valid_rows), _xlpm.supporters, INDEX(I:I, _xlpm.valid_rows), _xlpm.proj_scores, INDEX(M:M, _xlpm.valid_rows), _xlpm.indiv_totals, _xlfn.MAP(_xlpm.valid_rows, _xlfn.LAMBDA(_xlpm.r, SUM(_xlfn.MAP(_xlfn.CHOOSEROWS(D2:D300, _xlfn.SEQUENCE(IFERROR(INDEX(_xlpm.valid_rows, MATCH(_xlpm.r, _xlpm.valid_rows, 0)+1)-_xlpm.r, 301-_xlpm.r), 1, _xlpm.r-1)), _xlfn.LAMBDA(_xlpm.id, IFERROR(_xlfn.XLOOKUP(_xlpm.id, Source_Grades!A:A, Source_Grades!AA:AA, 0), 0)))))), _xlpm.sorted_data, _xlfn.SORTBY(_xlfn.HSTACK(_xlpm.leader_ids, _xlpm.supporters, _xlpm.proj_scores, _xlpm.indiv_totals), _xlpm.proj_scores, -1, _xlpm.indiv_totals, -1), _xlfn.TAKE(_xlpm.sorted_data, 10))} -> 2022170372 | AB6: Abdelrahman Sanad Yousif Ahmed | AC6: 0 | AD6: 224
A7: team 2 | B7: 1 | C7: ياسمين حسام عادل حسانين | D7: 20251701139 | E7: المستوى الأول/ Level 1 | F7: General (Mainstream) / عام | G7: 01118962030 | H7: 20251701139@cis.asu.edu.eg | I7: Menna Waheed | J7: 0 | K7: =IFERROR(_xlfn.XLOOKUP(D7, Project_Scores!$D:$D, Project_Scores!$F:$F, 0), 0) -> 0 | L7: =IFERROR(_xlfn.XLOOKUP(D7, Project_Scores!$D:$D, Project_Scores!$G:$G, 0), 0) -> 0 | M7: =SUM(J7,K7,L7) -> 0 | N7: =IFERROR(VLOOKUP(D7,Source_Grades!$A:$N,13,FALSE()),0) -> 116 | O7: =IFERROR(VLOOKUP(D7,Source_Grades!$A:$V,22,FALSE())*100,0) -> 83.333333 | P7: =IFERROR(VLOOKUP(D7,Source_Grades!$A:$Z,25,FALSE())*20,0) -> 100 | Q7: =IF(N7=0,0,N7/135*100) -> 85.925926 | R7: =O7 -> 83.333333 | S7: =IF(M7="",0,M7/145*100) -> 0 | T7: =Q7*0.2 + R7*0.3 + S7*0.5 -> 42.185185 | U7: =IF(R7>=60,"نعم","لا") -> نعم | V7: =IF(AND(T7>60,R7>=60),"ناجح","لم ينجح") -> لم ينجح | AA7: 20251701124 | AB7: Ahmed Ismail | AC7: 0 | AD7: 212
B8: 2 | C8: سما عباس سيد يوسف | D8: 20251700360 | E8: المستوى الأول/ Level 1 | F8: General (Mainstream) / عام | G8: 0 106 926 2702 | H8: 20251700360@cis.asu.edu.eg | J8: 0 | M8: =SUM(J8,K8,L8) -> 0 | N8: =IFERROR(VLOOKUP(D8,Source_Grades!$A:$N,13,FALSE()),0) -> 135 | O8: =IFERROR(VLOOKUP(D8,Source_Grades!$A:$V,22,FALSE())*100,0) -> 83.333333 | P8: =IFERROR(VLOOKUP(D8,Source_Grades!$A:$Z,25,FALSE())*20,0) -> 100 | Q8: =IF(N8=0,0,N8/135*100) -> 100 | R8: =O8 -> 83.333333 | S8: =IF(M8="",0,M8/145*100) -> 0 | T8: =Q8*0.2 + R8*0.3 + S8*0.5 -> 45 | U8: =IF(R8>=60,"نعم","لا") -> نعم | V8: =IF(AND(T8>60,R8>=60),"ناجح","لم ينجح") -> لم ينجح | AA8: 20241700920 | AB8: Nour gad | AC8: 0 | AD8: 199
B9: 3 | C9: اسماء احمد عزت عبدالمطلب | D9: 20251700097 | E9: المستوى الأول/ Level 1 | F9: General (Mainstream) / عام | G9: 01272781091 | H9: 20251700097@cis.asu.edu.eg | J9: 0 | M9: =SUM(J9,K9,L9) -> 0 | N9: =IFERROR(VLOOKUP(D9,Source_Grades!$A:$N,13,FALSE()),0) -> 119 | O9: =IFERROR(VLOOKUP(D9,Source_Grades!$A:$V,22,FALSE())*100,0) -> 83.333333 | P9: =IFERROR(VLOOKUP(D9,Source_Grades!$A:$Z,25,FALSE())*20,0) -> 100 | Q9: =IF(N9=0,0,N9/135*100) -> 88.148148 | R9: =O9 -> 83.333333 | S9: =IF(M9="",0,M9/145*100) -> 0 | T9: =Q9*0.2 + R9*0.3 + S9*0.5 -> 42.62963 | U9: =IF(R9>=60,"نعم","لا") -> نعم | V9: =IF(AND(T9>60,R9>=60),"ناجح","لم ينجح") -> لم ينجح | AA9: 20241700089 | AB9: Belal | AC9: 0 | AD9: 189
B10: 4 | C10: عمر ايمن بدر | D10: 20251700511 | E10: المستوى الأول/ Level 1 | F10: General (Mainstream) / عام | G10: 01013950802 | H10: 20251700511@cis.asu.edu.eg | J10: 0 | M10: =SUM(J10,K10,L10) -> 0 | N10: =IFERROR(VLOOKUP(D10,Source_Grades!$A:$N,13,FALSE()),0) -> 95 | O10: =IFERROR(VLOOKUP(D10,Source_Grades!$A:$V,22,FALSE())*100,0) -> 66.666667 | P10: =IFERROR(VLOOKUP(D10,Source_Grades!$A:$Z,25,FALSE())*20,0) -> 80 | Q10: =IF(N10=0,0,N10/135*100) -> 70.37037 | R10: =O10 -> 66.666667 | S10: =IF(M10="",0,M10/145*100) -> 0 | T10: =Q10*0.2 + R10*0.3 + S10*0.5 -> 34.074074 | U10: =IF(R10>=60,"نعم","لا") -> نعم | V10: =IF(AND(T10>60,R10>=60),"ناجح","لم ينجح") -> لم ينجح | AA10: 20251700957 | AB10: Ibrahim yousry | AC10: 0 | AD10: 189
B11: 5 | C11: عمر احمد محمد إسماعيل | D11: 20251700500 | E11: المستوى الأول/ Level 1 | F11: General (Mainstream) / عام | G11: 01018703667 | H11: 20251700500@cis.asu.edu.eg | J11: 0 | M11: =SUM(J11,K11,L11) -> 0 | N11: =IFERROR(VLOOKUP(D11,Source_Grades!$A:$N,13,FALSE()),0) -> 94 | O11: =IFERROR(VLOOKUP(D11,Source_Grades!$A:$V,22,FALSE())*100,0) -> 33.333333 | P11: =IFERROR(VLOOKUP(D11,Source_Grades!$A:$Z,25,FALSE())*20,0) -> 40 | Q11: =IF(N11=0,0,N11/135*100) -> 69.62963 | R11: =O11 -> 33.333333 | S11: =IF(M11="",0,M11/145*100) -> 0 | T11: =Q11*0.2 + R11*0.3 + S11*0.5 -> 23.925926 | U11: =IF(R11>=60,"نعم","لا") -> لا | V11: =IF(AND(T11>60,R11>=60),"ناجح","لم ينجح") -> لم ينجح | AA11: 2023170036 | AB11: Yousif Ahmed | AC11: 0 | AD11: 188
A12: team 3 | B12: 1 | C12: محمود محمد عبد الرسول كريم محمود | D12: 20251700762 | E12: المستوى الأول/ Level 1 | F12: General (Mainstream) / عام | G12: 01507359655 | H12: 20251700762@cis.asu.edu.eg | I12: Omar Mostafa | J12: 0 | K12: =IFERROR(_xlfn.XLOOKUP(D12, Project_Scores!$D:$D, Project_Scores!$F:$F, 0), 0) -> 0 | L12: =IFERROR(_xlfn.XLOOKUP(D12, Project_Scores!$D:$D, Project_Scores!$G:$G, 0), 0) -> 0 | M12: =SUM(J12,K12,L12) -> 0 | N12: =IFERROR(VLOOKUP(D12,Source_Grades!$A:$N,13,FALSE()),0) -> 77 | O12: =IFERROR(VLOOKUP(D12,Source_Grades!$A:$V,22,FALSE())*100,0) -> 83.333333 | P12: =IFERROR(VLOOKUP(D12,Source_Grades!$A:$Z,25,FALSE())*20,0) -> 100 | Q12: =IF(N12=0,0,N12/135*100) -> 57.037037 | R12: =O12 -> 83.333333 | S12: =IF(M12="",0,M12/145*100) -> 0 | T12: =Q12*0.2 + R12*0.3 + S12*0.5 -> 36.407407 | U12: =IF(R12>=60,"نعم","لا") -> نعم | V12: =IF(AND(T12>60,R12>=60),"ناجح","لم ينجح") -> لم ينجح | AA12: 20251700588 | AB12: Nour gad | AC12: 0 | AD12: 186
B13: 2 | C13: أحمد سالم السيد سليمان ربيع | D13: 20251700025 | E13: المستوى الأول/ Level 1 | F13: General (Mainstream) / عام | G13: 01200690946 | H13: 20251700025@cis.asu.edu.eg | J13: 0 | M13: =SUM(J13,K13,L13) -> 0 | N13: =IFERROR(VLOOKUP(D13,Source_Grades!$A:$N,13,FALSE()),0) -> 100 | O13: =IFERROR(VLOOKUP(D13,Source_Grades!$A:$V,22,FALSE())*100,0) -> 83.333333 | P13: =IFERROR(VLOOKUP(D13,Source_Grades!$A:$Z,25,FALSE())*20,0) -> 100 | Q13: =IF(N13=0,0,N13/135*100) -> 74.074074 | R13: =O13 -> 83.333333 | S13: =IF(M13="",0,M13/145*100) -> 0 | T13: =Q13*0.2 + R13*0.3 + S13*0.5 -> 39.814815 | U13: =IF(R13>=60,"نعم","لا") -> نعم | V13: =IF(AND(T13>60,R13>=60),"ناجح","لم ينجح") -> لم ينجح | AA13: 20241701016 | AB13: Shreif | AC13: 0 | AD13: 184.5
B14: 3 | C14: محمود طه أحمد محمد سيد | D14: 20251700758 | E14: المستوى الأول/ Level 1 | F14: General (Mainstream) / عام | G14: 01063681893 | H14: 20251700758@cis.asu.edu.eg | J14: 0 | M14: =SUM(J14,K14,L14) -> 0 | N14: =IFERROR(VLOOKUP(D14,Source_Grades!$A:$N,13,FALSE()),0) -> 92 | O14: =IFERROR(VLOOKUP(D14,Source_Grades!$A:$V,22,FALSE())*100,0) -> 83.333333 | P14: =IFERROR(VLOOKUP(D14,Source_Grades!$A:$Z,25,FALSE())*20,0) -> 100 | Q14: =IF(N14=0,0,N14/135*100) -> 68.148148 | R14: =O14 -> 83.333333 | S14: =IF(M14="",0,M14/145*100) -> 0 | T14: =Q14*0.2 + R14*0.3 + S14*0.5 -> 38.62963 | U14: =IF(R14>=60,"نعم","لا") -> نعم | V14: =IF(AND(T14>60,R14>=60),"ناجح","لم ينجح") -> لم ينجح | AA14: 20241701056 | AB14: Mohamed Taher | AC14: 0 | AD14: 183
B15: 4 | C15: عمر سعيد إسماعيل السيد فروح | D15: 20251700521 | E15: المستوى الأول/ Level 1 | F15: General (Mainstream) / عام | G15: 01127183750 | H15: 20251700521@cis.asu.edu.eg | J15: 0 | M15: =SUM(J15,K15,L15) -> 0 | N15: =IFERROR(VLOOKUP(D15,Source_Grades!$A:$N,13,FALSE()),0) -> 92 | O15: =IFERROR(VLOOKUP(D15,Source_Grades!$A:$V,22,FALSE())*100,0) -> 83.333333 | P15: =IFERROR(VLOOKUP(D15,Source_Grades!$A:$Z,25,FALSE())*20,0) -> 100 | Q15: =IF(N15=0,0,N15/135*100) -> 68.148148 | R15: =O15 -> 83.333333 | S15: =IF(M15="",0,M15/145*100) -> 0 | T15: =Q15*0.2 + R15*0.3 + S15*0.5 -> 38.62963 | U15: =IF(R15>=60,"نعم","لا") -> نعم | V15: =IF(AND(T15>60,R15>=60),"ناجح","لم ينجح") -> لم ينجح | AA15: 20241701169 | AB15: Shreif | AC15: 0 | AD15: 178
B16: 5 | C16: ملك حسين علي عبداللاه | D16: 20251701741 | E16: المستوى الأول/ Level 1 | F16: هندسة البرمجيات/ Software Engineer | G16: 01062418859 | H16: 20251701741@cis.asu.edu.eg | J16: 0 | M16: =SUM(J16,K16,L16) -> 0 | N16: =IFERROR(VLOOKUP(D16,Source_Grades!$A:$N,13,FALSE()),0) -> 87.5 | O16: =IFERROR(VLOOKUP(D16,Source_Grades!$A:$V,22,FALSE())*100,0) -> 83.333333 | P16: =IFERROR(VLOOKUP(D16,Source_Grades!$A:$Z,25,FALSE())*20,0) -> 100 | Q16: =IF(N16=0,0,N16/135*100) -> 64.814815 | R16: =O16 -> 83.333333 | S16: =IF(M16="",0,M16/145*100) -> 0 | T16: =Q16*0.2 + R16*0.3 + S16*0.5 -> 37.962963 | U16: =IF(R16>=60,"نعم","لا") -> نعم | V16: =IF(AND(T16>60,R16>=60),"ناجح","لم ينجح") -> لم ينجح
A17: team 4 | B17: 1 | C17: عل محمد منير علي زكي | D17: 20251701124 | E17: المستوى الأول/ Level 1 | F17: General (Mainstream) / عام | G17: 01226469696 | H17: 20251701124@cis.asu.edu.eg | I17: Ahmed Ismail | J17: 0 | K17: =IFERROR(_xlfn.XLOOKUP(D17, Project_Scores!$D:$D, Project_Scores!$F:$F, 0), 0) -> 0 | L17: =IFERROR(_xlfn.XLOOKUP(D17, Project_Scores!$D:$D, Project_Scores!$G:$G, 0), 0) -> 0 | M17: =SUM(J17,K17,L17) -> 0 | N17: =IFERROR(VLOOKUP(D17,Source_Grades!$A:$N,13,FALSE()),0) -> 137 | O17: =IFERROR(VLOOKUP(D17,Source_Grades!$A:$V,22,FALSE())*100,0) -> 83.333333 | P17: =IFERROR(VLOOKUP(D17,Source_Grades!$A:$Z,25,FALSE())*20,0) -> 100 | Q17: =IF(N17=0,0,N17/135*100) -> 101.48148 | R17: =O17 -> 83.333333 | S17: =IF(M17="",0,M17/145*100) -> 0 | T17: =Q17*0.2 + R17*0.3 + S17*0.5 -> 45.296296 | U17: =IF(R17>=60,"نعم","لا") -> نعم | V17: =IF(AND(T17>60,R17>=60),"ناجح","لم ينجح") -> لم ينجح
B18: 2 | C18: عبدالله كرم ابوزيد سيف | D18: 20251700432 | E18: المستوى الأول/ Level 1 | F18: General (Mainstream) / عام | G18: 01093493111 | H18: 20251700432@cis.asu.edu.eg | J18: 0 | M18: =SUM(J18,K18,L18) -> 0 | N18: =IFERROR(VLOOKUP(D18,Source_Grades!$A:$N,13,FALSE()),0) -> 122.5 | O18: =IFERROR(VLOOKUP(D18,Source_Grades!$A:$V,22,FALSE())*100,0) -> 83.333333 | P18: =IFERROR(VLOOKUP(D18,Source_Grades!$A:$Z,25,FALSE())*20,0) -> 100 | Q18: =IF(N18=0,0,N18/135*100) -> 90.740741 | R18: =O18 -> 83.333333 | S18: =IF(M18="",0,M18/145*100) -> 0 | T18: =Q18*0.2 + R18*0.3 + S18*0.5 -> 43.148148 | U18: =IF(R18>=60,"نعم","لا") -> نعم | V18: =IF(AND(T18>60,R18>=60),"ناجح","لم ينجح") -> لم ينجح
B19: 3 | C19: بيشوي امجد فوزي عبدالملاك | D19: 2023170147 | E19: المستوى الثالث/ Level 3 | F19: الحسابات العلمية/ Scientific Computing | G19: 01228898234 | H19: 2023170147@cis.asu.edu.eg | J19: 0 | M19: =SUM(J19,K19,L19) -> 0 | N19: =IFERROR(VLOOKUP(D19,Source_Grades!$A:$N,13,FALSE()),0) -> 134 | O19: =IFERROR(VLOOKUP(D19,Source_Grades!$A:$V,22,FALSE())*100,0) -> 83.333333 | P19: =IFERROR(VLOOKUP(D19,Source_Grades!$A:$Z,25,FALSE())*20,0) -> 100 | Q19: =IF(N19=0,0,N19/135*100) -> 99.259259 | R19: =O19 -> 83.333333 | S19: =IF(M19="",0,M19/145*100) -> 0 | T19: =Q19*0.2 + R19*0.3 + S19*0.5 -> 44.851852 | U19: =IF(R19>=60,"نعم","لا") -> نعم | V19: =IF(AND(T19>60,R19>=60),"ناجح","لم ينجح") -> لم ينجح
